Workbook

Sheet Instructions
A1: SE Team Workbook
A2: Introduction to Software Engineering | Sem01_2627 | One workbook per team, kept in your shared Google Drive folder
A4: Purpose
A5: This workbook is your team's working record for the whole 7-week project. It holds your Ambiguity Log and questions to the instructor, the requirements, the plan, the Requirements Traceability Matrix (RTM), your test cases and the other tables the project asks for. Keep it in your team's shared Google Drive folder (share it with the instructor). The instructor reads it and replies in the green cells. It does not replace the official submission on eLearning.
A7: How the Ambiguity Log and questions work
A8: 1. The specification deliberately leaves details open (for example how a shipper is chosen, or what is refunded after a failed delivery). Record each gap in the Ambiguity Log sheet, with the assumption your team would make if nobody answers.
A9: 2. Discuss each one as a team first. If you want the instructor's view, set its status to "Asked". Do not ask what the specification already answers.
A10: 3. The instructor answers in the green cells. Copy the final decision into the "Final decision" column and use it in your requirements, design and tests.
A11: 4. You need at least 3 ambiguities in your Part 1 document. Unrecorded assumptions are not accepted as an excuse for a missing requirement.
A13: Colour legend
A14: Student input | B14: Yellow fill, blue text
A15: Instructor input | B15: Green fill, blue text
A16: Calculated / fixed | B16: Black text, no fill
A18: Sheets in this workbook
A19: Sheet | B19: Project requirement it supports | C19: Used in | D19: Fill in
A20: Team & Tier | B20: Team, chosen tier and cap, at least one main use case (CRUD) per student | C20: Part 1 | D20: Week 1
A21: Ambiguity Log | B21: At least 3 ambiguities with assumptions and instructor answers | C21: Part 1 | D21: Week 1-2 and later
A22: Requirements | B22: FRs and NFRs with IDs, mapped to use cases, BRs and reports; measurable NFRs | C22: Part 1; RTM | D22: Part 1 on
A23: Plan & Risks | B23: 7-week plan, task board and risk list | C23: Part 1 proposal | D23: Throughout
A24: EP-BVA Planner | B24: Partitions and boundary values for every threshold (BR1 to BR12, BR14); at least 20 test cases | C24: Part 3 QA report | D24: Part 2 to 3
A25: Test Cases | B25: Test plan: ID, input, expected, actual, pass/fail, FR and BR IDs | C25: Part 3 QA report | D25: Part 3
A26: State Tests | B26: Valid transition coverage and at least 5 invalid order-state transition tests (BR15) | C26: Part 3 QA report | D26: Part 3
A27: RTM | B27: Every FR and NFR linked to use case, design, code and tests, with verdict | C27: Part 3 | D27: Part 1 on
A28: Change Request | B28: One-page Change Request Impact Note and the class change list | C28: Part 3 (Week 5) | D28: Week 5
A29: Tier Checklist | B29: Checks that you really deliver the stack, architecture and extras of your tier | C29: Part 1 to 3 | D29: Throughout
A30: Contribution & Commits | B30: Contribution Statement draft and commits per student (more than 10) | C30: Part 3; contribution factor | D30: Throughout
... A32: Feedback Log | B32: Feedback from each presentation and marking, and what you changed | C32: Final report | D32: After each feedback

Sheet Team & Tier
A1: Team, Tier and Use Case Ownership
A2: Each student owns at least one main use case with complete CRUD. "Place and Manage Orders" must be owned by one team member.
A4: Team name | B4: TeamG4
A5: Chosen tier | B5: Tier 4
A6: Tier cap (/10) | B6: =IF(B7<>"",IFERROR(VLOOKUP(B7,$A$37:$B$41,2,FALSE()),""),IFERROR(VLOOKUP(B5,$A$37:$B$41,2,FALSE()),"")) -> 10
A7: Instructor confirmed tier
A8: Team size | B8: =COUNTA(B11:B13) -> 3
A10: Member | B10: Name | C10: Student ID | D10: Role | E10: Main use cases owned | F10: Commits (see Contribution sheet) | G10: Check
A11: Member 1 | B11: Ngô Lâm Tiến | C11: 524H0195 | D11: D owner: Place and Manage Orders. Planned peer reviewer: 524H0179. | E11: =IF(C11="","",COUNTIF($F$18:$F$25,C11)) -> 2 | F11: =IF(C11="","",'Contribution & Commits'!D5) -> Not verified | G11: =IF(C11="","",IF(E11>=1,"OK","Needs at least 1 main use case")) -> OK
A12: Member 2 | B12: Nguyễn Công Thành | C12: 524H0191 | D12: A owner: Manage Menu & Brands. Planned peer reviewer: 524H0195. | E12: =IF(C12="","",COUNTIF($F$18:$F$25,C12)) -> 2 | F12: =IF(C12="","",'Contribution & Commits'!D6) -> Not verified | G12: =IF(C12="","",IF(E12>=1,"OK","Needs at least 1 main use case")) -> OK
A13: Member 3 | B13: Nguyễn Trọng Phú | C13: 524H0179 | D13: B owner: Manage Hubs & Capacity. Planned peer reviewer: 524H0191. | E13: =IF(C13="","",COUNTIF($F$18:$F$25,C13)) -> 2 | F13: =IF(C13="","",'Contribution & Commits'!D7) -> Not verified | G13: =IF(C13="","",IF(E13>=1,"OK","Needs at least 1 main use case")) -> OK
A16: Main use cases (candidate list A to F in the specification, or your own approved proposal)
A17: No. | B17: Use case | C17: Spec item | D17: CRUD meaning | E17: Status | F17: Owner (student ID) | G17: Instructor comment
A18: UC1 | B18: Place and Manage Orders | C18: D | D18: Create; track/read; edit in Placed; cancel in Placed/Confirmed (retain history). | E18: Idea | F18: 524H0195
A19: UC2 | B19: Manage Menu & Brands | C19: A | D19: Create; browse/filter; update details/availability; soft-delete. | E19: Idea | F19: 524H0191
A20: UC3 | B20: Manage Hubs & Capacity | C20: B | D20: Create; view load; update address/capacity; soft-delete. | E20: Idea | F20: 524H0179
A21: UC4 | B21: Manage Vouchers | C21: C | D21: Create; read; edit; deactivate vouchers. Secondary scope. | E21: Idea | F21: 524H0195
A22: UC5 | B22: Manage User Accounts | C22: E | D22: Register; read; edit; deactivate accounts. Secondary scope. | E22: Idea | F22: 524H0191
A23: UC6 | B23: Manage Deliveries | C23: F | D23: Create assignment; read; update delivery status; reassign before dispatch. Secondary scope. | E23: Idea | F23: 524H0179
A24: UC7
A25: UC8
A27: "Place and Manage Orders" owned? | D27: =IF(SUMPRODUCT((ISNUMBER(SEARCH("Place and Manage Orders",B18:B25)))*(F18:F25<>""))>0,"OK","Missing owner") -> OK
A28: Pricing and payment module owner | D28: 524H0195
A29: The pricing and payment module (BR1 to BR14) is shared team infrastructure. Its named owner is the student who owns "Place and Manage Orders".
A35: Technology tiers (from the specification; the instructor may edit the blue caps)
A36: Tier | B36: Max score (/10) | C36: Stack and architecture
A37: Tier 1 | B37: 7 | C37: C# WinForms + local SQL database / Excel. 3-Tier architecture.
A38: Tier 1B | B38: 7.5 | C38: Core PHP (or CodeIgniter) + MySQL + Bootstrap. MVC architecture.
A39: Tier 2 | B39: 8.5 | C39: ASP.NET Web Forms/MVC (Database First) + SQL Server + Bootstrap. MVC.
A40: Tier 3 | B40: 9.5 | C40: ASP.NET MVC (Code First) + Entity Framework + Bootstrap. MVC.
A41: Tier 4 | B41: 10 | C41: Tier 3 plus live sandbox API, interactive Admin dashboard and automated tests.

Sheet Ambiguity Log
A1: Ambiguity Log and Questions to the Instructor
A2: At least 3 ambiguities, gaps or conflicts in the specification, each with your assumption. Ask only what the specification does not answer.
A4: ID | B4: Type | C4: Where in the specification and what is unclear | D4: Question to the instructor (optional) | E4: Team discussion and our assumption (if no answer) | F4: Status | G4: Instructor answer | H4: Date | I4: Final decision / assumption we use | J4: Affects (FR / BR / UC)
A5: A1 | B5: Ambiguity | C5: Shipper assignment. Section 2C leaves the assignment mechanism open. | D5: May an Admin manually assign an available shipper to a Ready order? | E5: An Admin manually selects an available shipper for a Ready order. The system stores assignment time and shipper. Automatic dispatch is outside the initial scope. | F5: Draft | I5: An Admin manually selects an available shipper for a Ready order. The system stores assignment time and shipper. Automatic dispatch is outside the initial scope. | J5: FR-F1; UC F; assignment screen and service.
A6: A2 | B6: Ambiguity | C6: Settlement after Failed delivery. Section 2C leaves the financial result of Failed delivery open. | D6: For Failed delivery, should online payments be refunded in full and COD collect no cash? | E6: Refund online-paid orders in full in the simulated ledger; collect no COD cash. Preserve Failed as its own terminal state and exclude it from R1 revenue. | F6: Draft | I6: Refund online-paid orders in full in the simulated ledger; collect no COD cash. Preserve Failed as its own terminal state and exclude it from R1 revenue. | J6: FR-F4; UC F/D; payment/refund policy and R1.
A7: A3 | B7: Ambiguity | C7: Tourist delivery address. Hotel and room are allowed, but a field structure is not prescribed. | D7: May we use address text with optional hotel name and room for a tourist? | E7: Store street/address text plus optional hotel name and room. Require a usable delivery address for either customer type; tourists are not required to supply a Vietnamese phone. | F7: Draft | I7: Store street/address text plus optional hotel name and room. Require a usable delivery address for either customer type; tourists are not required to supply a Vietnamese phone. | J7: FR-E2 and FR-D1; address validation and checkout.
A8: A4 | B8: Ambiguity | C8: Invalid voucher user flow. BR9 specifies eligibility but not whether a refused voucher should block the whole order. | D8: May we refuse the voucher and request explicit confirmation of the corrected total? | E8: Show the refusal and the corrected breakdown with V=0; require the customer to review and confirm that total before placing the order. Never silently submit a higher total. | F8: Draft | I8: Show the refusal and the corrected breakdown with V=0; require the customer to review and confirm that total before placing the order. Never silently submit a higher total. | J8: FR-C3 and FR-D9/D11; checkout confirmation.
A9: A5 | B9: Ambiguity | C9: Catalogue price change before a Placed edit. BR17 fixes timestamp/load/rain but does not explicitly say which item prices apply when the catalogue changes before an edit. | D9: On a Placed edit after a catalogue price change, should existing lines retain recorded prices and new lines use current prices? | E9: Existing lines retain their recorded unit prices; newly added items use the current catalogue price after availability/membership validation. Recalculation still uses the original timestamp, load and rain snapshot. | F9: Draft | I9: Existing lines retain their recorded unit prices; newly added items use the current catalogue price after availability/membership validation. Recalculation still uses the original timestamp, load and rain snapshot. | J9: FR-D12/D14 and FR-A4; order-line price storage and edit tests.
A10: A-06
A11: A-07
A12: A-08
A13: A-09
A14: A-10
A15: A-11
A16: A-12
A17: A-13
A18: A-14
A19: A-15
C21: Number of ambiguities logged | D21: =COUNTA(C5:C19) -> 5
C22: Check (need at least 3) | D22: =IF(D21>=3,"OK","Need at least 3") -> OK

Sheet Requirements
A1: Requirements
A2: Functional ("The system shall…") and non-functional requirements with IDs. Non-functional requirements need a measurable target.
A4: ID | B4: Requirement | C4: Type | D4: Priority | E4: Use case | F4: Business rules (BR) | G4: Report (R1 / R2) | H4: Owner (ID) | I4: Measurable target (NFR) / acceptance note | J4: Instructor comment | K4: Status
A5: FR-A1 | B5: The system shall let an administrator create a brand (name, description, operating hubs) and create its menu items (name, category, positive VND price, brand and availability). | C5: FR | D5: High | E5: A | F5: BR12 | G5: — | H5: 524H0191 | I5: Planned acceptance: TC-A-01. Source: BR12. | K5: Draft
A6: FR-A2 | B6: The system shall let any visitor view brands and menu items filtered by hub and by category. | C6: FR | D6: High | E6: A | F6: BR12 | G6: — | H6: 524H0191 | I6: Planned acceptance: TC-A-02. Source: BR12. | K6: Draft
A7: FR-A3 | B7: The system shall let an administrator edit brand details and a menu item’s name, category, price and brand. | C7: FR | D7: High | E7: A | F7: BR12 | G7: — | H7: 524H0191 | I7: Planned acceptance: TC-A-03. Source: BR12. | K7: Draft
A8: FR-A4 | B8: The system shall soft-delete brands and menu items, so that historical orders and reports keep their names and prices. | C8: FR | D8: High | E8: A | F8: BR12 | G8: — | H8: 524H0191 | I8: Planned acceptance: TC-A-04. Source: BR12. | K8: Draft
A9: FR-A5 | B9: The system shall let an administrator set item availability; unavailable or inactive items shall not be orderable. | C9: FR | D9: High | E9: A | F9: BR12 | G9: — | H9: 524H0191 | I9: Planned acceptance: TC-A-05. Source: BR12. | K9: Draft
A10: FR-A6 | B10: The system shall reject any order line whose item belongs to a brand the chosen hub does not operate. | C10: FR | D10: High | E10: A | F10: BR12 | G10: — | H10: 524H0191 | I10: Planned acceptance: TC-A-06. Source: BR12. | K10: Draft
A11: FR-B1 | B11: The system shall let an administrator create a hub with a district, an address and a whole-number kitchen capacity greater than zero. | C11: FR | D11: High | E11: B | F11: BR8 | G11: — | H11: 524H0179 | I11: Planned acceptance: TC-B-01. Source: BR8. | K11: Draft
A12: FR-B2 | B12: The system shall display hub load as 100 times the count of Confirmed or Preparing orders divided by positive integer kitchen capacity; the new order is not counted. | C12: FR | D12: High | E12: B | F12: BR8 | G12: — | H12: 524H0179 | I12: Planned acceptance: TC-B-02. Source: BR8. | K12: Draft
A13: FR-B3 | B13: The system shall let an administrator edit a hub’s district, address and positive integer capacity, and recompute displayed load after a capacity change. | C13: FR | D13: High | E13: B | F13: BR8 | G13: — | H13: 524H0179 | I13: Planned acceptance: TC-B-03. Source: BR8. | K13: Draft
A14: FR-B4 | B14: The system shall soft-delete a hub, removing it from ordering while preserving its historical orders and report rows. | C14: FR | D14: High | E14: B | F14: BR8 | G14: — | H14: 524H0179 | I14: Planned acceptance: TC-B-04. Source: BR8. | K14: Draft
A15: FR-B5 | B15: The system shall refuse a new order when the chosen hub’s load is 90 % or above and shall ask the customer to choose another hub. | C15: FR | D15: High | E15: B | F15: BR8 | G15: — | H15: 524H0179 | I15: Planned acceptance: TC-B-05. Source: BR8. | K15: Draft
A16: FR-C1 | B16: The system shall let an administrator create a voucher with a code, a type (PERCENT or FIXED), a value, a maximum discount, a minimum subtotal, validity dates and an active flag. | C16: FR | D16: High | E16: C | F16: BR9 | G16: — | H16: 524H0195 | I16: Planned acceptance: TC-C-01. Source: BR9. | K16: Draft
... A57: NFR6 | B57: Reliability: Zero forbidden transitions are accepted; repeated pricing with identical lines and the stored placement snapshot returns identical components and rounded total. | C57: NFR | D57: Medium | E57: D/F | F57: Team-defined; BR10, BR11, BR15, BR17 | G57: — | H57: 524H0195 / 524H0179 | I57: Team-defined. Enumerate the state/actor matrix, include at least five forbidden transitions, and repeat boundary pricing inputs against a fixed snapshot. | K57: Draft
B59: Number of FRs / NFRs | C59: =COUNTIF(C5:C57,"FR") -> 47 | D59: =COUNTIF(C5:C57,"NFR") -> 6
B60: NFR check (4 baselines + at least 2 of your own = 6) | D60: =IF(D59>=6,"OK","Need 6") -> OK

Sheet Plan & Risks
A1: 7-Week Plan, Task Board and Risks
A2: Part 1 (Weeks 1-2), Part 2 (Weeks 3-4), Part 3 (Weeks 5-7). Week 5: running skeleton checkpoint and the Change Request.
A4: Week | B4: Milestone (fixed) | C4: Planned work | D4: Who (IDs) | E4: Deliverable | F4: Status | G4: Notes | H4: Instructor comment
A5: Week 1 | B5: Part 1: requirements and proposal | C5: Analyse BR1–BR18; assign D/A/B; draft 47 FR, 6 NFR and 5 ambiguities. | D5: 524H0195, 524H0191, 524H0179 | E5: Part 1 report and shared workbook | F5: Planned | G5: Scrum plan: shared backlog and short daily coordination. Peer review rotation: 524H0179 reviews 524H0195; 524H0195 reviews 524H0191; 524H0191 reviews 524H0179. Record findings before milestone review.
A6: Week 2 | B6: Part 1: Presentation 1 (Solution Pitch) | C6: Review report/workbook; rehearse all 3 speakers and submit the Solution Pitch. | D6: 524H0195, 524H0191, 524H0179 | E6: Part 1 report, workbook, 5-slide pitch | F6: Planned | G6: Due 26 Oct 2026, 07:00 UTC+7. Planned speaking time 6:15; rehearsal pending.
A7: Week 3 | B7: Part 2: UML, CRC, architecture | C7: Model each owned use case; state machine; CRC; class/ERD; MVC and payment Strategy. | D7: 524H0195, 524H0191, 524H0179 | E7: Part 2 design draft | F7: Planned | G7: Review mappings from FR/NFR IDs to design elements.
A8: Week 4 | B8: Part 2: Figma and Presentation 2 (Design Review) | C8: Validate Figma screens and UML; present Design Review; apply received feedback. | D8: 524H0195, 524H0191, 524H0179 | E8: Part 2 report, prototype, Presentation 2 | F8: Planned | G8: Due 9 Nov 2026, 07:00 UTC+7. Public Figma link required.
A9: Week 5 | B9: Part 3: running skeleton checkpoint, Change Request issued | C9: Demonstrate running skeleton; analyse the actual instructor change request. | D9: 524H0195, 524H0191, 524H0179 | E9: Skeleton checkpoint and Change Request Impact Note | F9: Planned | G9: Phú coordinates impact note; Tiến owns payment extension boundary. No issued change invented.
A10: Week 6 | B10: Part 3: implementation and QA | C10: Implement D/A/B and secondary C/E/F; integrate sandbox, dashboards and automated QA. | D10: 524H0195, 524H0191, 524H0179 | E10: Integrated application and execution evidence | F10: Planned | G10: At least 20 EP/BVA cases plus 5 invalid-transition tests.
A11: Week 7 | B11: Part 3: final demo, report and video | C11: Complete RTM, QA, demo/video and contribution records; tag and submit Part 3. | D11: 524H0195, 524H0191, 524H0179 | E11: Part 3 code/QA/demo package | F11: Planned | G11: Part 3 due 30 Nov 2026, 07:00 UTC+7. Separate final consolidation: 7 Dec; confirm portal.
A13: Task board
A14: ID | B14: Task | C14: Related FR / UC | D14: Owner (ID) | E14: Week | F14: Status | G14: Link / evidence | H14: Instructor comment
A15: T01 | B15: Baseline FR/NFR and order/pricing acceptance criteria | C15: D; BR1–BR18 | D15: 524H0195 | E15: 1 | F15: In progress | G15: Report §§1.3–1.4; Requirements. Planned reviewer: 524H0179; check load, lifecycle and delivery boundaries with 524H0195.
A16: T02 | B16: Catalogue/accounts and R1 requirement review | C16: A/E; R1 | D16: 524H0191 | E16: 1 | F16: To do | G16: Report §§1.1/1.3. Planned reviewer: 524H0195; check catalogue-to-checkout and R1/payment consistency with 524H0191.
A17: T03 | B17: Hub/delivery and R2 requirement review | C17: B/F; R2 | D17: 524H0179 | E17: 1 | F17: To do | G17: Report §§1.1/1.3. Planned reviewer: 524H0191; check hub/catalogue membership and R2 data with 524H0179.
A18: T04 | B18: Rehearse Solution Pitch and coordinate Part 1 submission | C18: D/A/B | D18: 524H0195 | E18: 2 | F18: To do | G18: Shared pitch notes; all 3 speakers claim D/A/B. Planned joint rehearsal checks handovers, one client journey and cross-scope questions.
A19: T05 | B19: Order state and payment Strategy UML | C19: D; BR13–BR17 | D19: 524H0195 | E19: 3 | F19: To do | G19: Planned Part 2 UML/CRC. Reviewer 524H0179 checks order/delivery guards; 524H0191 checks account/payment and catalogue dependencies.
A20: T06 | B20: Catalogue/accounts and R1 UI prototype | C20: A/E; R1 | D20: 524H0191 | E20: 4 | F20: To do | G20: Planned Figma/design review. Reviewer 524H0195 checks checkout/R1 flow; 524H0179 checks hub context.
A21: T07 | B21: Hub/delivery design and Change Request impact | C21: B/F; R2 | D21: 524H0179 | E21: 5 | F21: To do | G21: Actual Week 5 request only. Reviewer 524H0191 checks R2/data impact; 524H0195 checks payment/pricing impact.
A22: T08 | B22: Live sandbox integration and core automated tests | C22: D; BR1–BR18 | D22: 524H0195 | E22: 6 | F22: To do | G22: Planned reviewers 524H0191 and 524H0179; retain redacted callbacks and joint regression logs, at least 20 EP/BVA and 5 invalid transitions.
A23: T09 | B23: Interactive R1/R2 Admin dashboard and access checks | C23: R1/R2 | D23: 524H0191 / 524H0179 | E23: 6 | F23: To do | G23: Planned reviewer 524H0195; reconcile chart/table totals with payment outcomes and delivery/load data owned by 524H0191/524H0179.
A24: T10 | B24: Agree shared hub/menu/order/payment contracts | C24: D/A/B; FR-A6; FR-D14 | D24: 524H0195 | E24: 2 | F24: To do | G24: Planned joint review: all 3 members agree hub membership, availability, capacity, placement snapshot and payment boundaries; record decisions against FR IDs.
A25: T11 | B25: Cross-review requirements and assumptions before baseline | C25: 47 FR; 6 NFR; A1–A5 | D25: 524H0191 | E25: 2 | F25: To do | G25: Planned rotation: 524H0179 reviews D/C; 524H0195 reviews A/E; 524H0191 reviews B/F. Resolve comments in the shared register/RTM; retain reviewer links.
A26: T12 | B26: Joint end-to-end integration and release review | C26: A/B/D/F; R1/R2 | D26: 524H0179 | E26: 6 | F26: To do | G26: Planned all-member journey: browse menu, select hub, checkout/pay, prepare/deliver, reconcile R1/R2. Retain scoped PRs, peer comments and linked test logs.
A27: T13
A28: T14
A29: T15
A30: T16
A31: T17
A32: T18
A33: T19
A34: T20
A35: T21
A36: T22
A37: T23
A38: T24
... A41: Risk list
A42: ID | B42: Risk description | C42: Likelihood | D42: Impact | E42: Score | F42: Owner (ID) | G42: Status | H42: Mitigation / instructor comment
A43: R-01 | B43: Sandbox credentials/provider availability could prevent live Tier 4 evidence. | C43: High | D43: High | E43: =IF(OR(C43="",D43=""),"",(MATCH(C43,{"Low","Medium","High"},0))*(MATCH(D43,{"Low","Medium","High"},0))) -> 9 | F43: 524H0195 | G43: Open | H43: Arrange credentials early; retain real redacted callbacks. Label simulation; do not count it as live evidence.
A44: R-02 | B44: Core MVC/EF Core variant has not been confirmed against the instructor tier wording. | C44: Medium | D44: High | E44: =IF(OR(C44="",D44=""),"",(MATCH(C44,{"Low","Medium","High"},0))*(MATCH(D44,{"Low","Medium","High"},0))) -> 6 | F44: 524H0195 | G44: Open | H44: Ask instructor to confirm the proposed foundation before claiming Tier 4 eligibility.
...

Sheet EP-BVA Planner
A1: Equivalence Partitioning and Boundary Value Planner
A2: Plan partitions and boundary values for every numeric threshold in BR1 to BR12 and BR14. At least 20 EP/BVA test cases in total.
A4: Rule | B4: Threshold under test | C4: Partitions (valid / invalid) | D4: Boundary values to test | E4: Test IDs (comma separated) | F4: Tests | G4: Instructor comment
A5: BR1 | B5: Minimum order subtotal | F5: =IF(E5="","",LEN(E5)-LEN(SUBSTITUTE(E5,",",""))+1)
A6: BR2 | B6: Coverage distance | F6: =IF(E6="","",LEN(E6)-LEN(SUBSTITUTE(E6,",",""))+1)
A7: BR3 | B7: Delivery fee bands (distance) | F7: =IF(E7="","",LEN(E7)-LEN(SUBSTITUTE(E7,",",""))+1)
A8: BR4 | B8: Rush-hour windows (time) | F8: =IF(E8="","",LEN(E8)-LEN(SUBSTITUTE(E8,",",""))+1)
A9: BR6 | B9: Free-delivery threshold | F9: =IF(E9="","",LEN(E9)-LEN(SUBSTITUTE(E9,",",""))+1)
A10: BR7 | B10: Quiet Kitchen load threshold | F10: =IF(E10="","",LEN(E10)-LEN(SUBSTITUTE(E10,",",""))+1)
A11: BR8 | B11: Hub load protection | F11: =IF(E11="","",LEN(E11)-LEN(SUBSTITUTE(E11,",",""))+1)
A12: BR9 | B12: Voucher cap and minimum subtotal | F12: =IF(E12="","",LEN(E12)-LEN(SUBSTITUTE(E12,",",""))+1)
A13: BR11 | B13: Rounding to nearest 1,000 | F13: =IF(E13="","",LEN(E13)-LEN(SUBSTITUTE(E13,",",""))+1)
A14: BR12 | B14: Quantity per line and lines per order | F14: =IF(E14="","",LEN(E14)-LEN(SUBSTITUTE(E14,",",""))+1)
A15: BR14 | B15: COD limit | F15: =IF(E15="","",LEN(E15)-LEN(SUBSTITUTE(E15,",",""))+1)
A16: Other | B16: Any other threshold you found | F16: =IF(E16="","",LEN(E16)-LEN(SUBSTITUTE(E16,",",""))+1)
B18: Total EP/BVA test cases planned | C18: =SUM(F5:F16) -> 0
B19: EP/BVA tests recorded on the Test Cases sheet | C19: =COUNTIF('Test Cases'!E5:E64,"EP")+COUNTIF('Test Cases'!E5:E64,"BVA") -> 0
B20: Check (need at least 20) | C20: =IF(C19>=20,"OK","Need at least 20") -> Need at least 20
A22: Boundary values to think about: just below, exactly at, and just above each threshold (for example 49,999 / 50,000 / 50,001). Time windows are inclusive at the start and exclusive at the end.

Sheet Test Cases
A1: Test Cases
A2: Table of test cases with Test ID, description, input, expected, actual and pass/fail, plus the FR and BR IDs each case covers.
A4: Test ID | B4: Use case | C4: FR | D4: BR | E4: Technique | F4: Description | G4: Input data / steps | H4: Expected result | I4: Actual result | J4: Pass / fail | K4: Tested by (ID) | L4: Date | M4: Instructor comment
A5: T-01
A6: T-02
A7: T-03
A8: T-04
A9: T-05
A10: T-06
A11: T-07
A12: T-08
A13: T-09
A14: T-10
A15: T-11
A16: T-12
... A64: T-60
F66: Pass | G66: =COUNTIF(J5:J64,"Pass") -> 0
F67: Fail | G67: =COUNTIF(J5:J64,"Fail") -> 0
F68: Not run | G68: =COUNTIF(J5:J64,"Not run") -> 0
F69: Pass rate (of tests run) | G69: =IFERROR(G66/(G66+G67),"")
F70: EP + BVA test cases (need 20) | G70: =COUNTIF(E5:E64,"EP")+COUNTIF(E5:E64,"BVA") -> 0
F71: State tests (need 5 invalid) | G71: =COUNTA('State Tests'!B17:B31) -> 0

Sheet State Tests
A1: Order State Machine Tests (BR15)
A2: Cover every allowed transition, and try at least 5 invalid transitions. The business layer, not only the UI, must reject invalid ones.
A3: Allowed transitions (from the specification)
A4: No. | B4: From | C4: To | D4: Allowed actor | E4: Condition | F4: Covered by test ID | G4: Tested OK?
A5: 1 | B5: Placed | C5: Confirmed | D5: Kitchen Staff | E5: Hub of the order
A6: 2 | B6: Placed | C6: Cancelled | D6: Customer or Kitchen Staff | E6: Kitchen must give a reason
A7: 3 | B7: Confirmed | C7: Preparing | D7: Kitchen Staff | E7: –
A8: 4 | B8: Confirmed | C8: Cancelled | D8: Customer or Admin | E8: –
A9: 5 | B9: Preparing | C9: Ready | D9: Kitchen Staff | E9: –
A10: 6 | B10: Ready | C10: Out for Delivery | D10: Shipper | E10: A shipper is assigned
A11: 7 | B11: Out for Delivery | C11: Delivered | D11: Shipper | E11: COD: cash confirmed (BR14)
A12: 8 | B12: Out for Delivery | C12: Failed | D12: Shipper | E12: Customer unreachable
E13: Coverage | F13: =COUNTIF(G5:G12,"Yes")&" of 8" -> 0 of 8
A15: Invalid transition tests (at least 5)
A16: Test ID | B16: Test ID in Test Cases | C16: From state | D16: Attempted state | E16: Actor | F16: Expected result | G16: Actual result | H16: Pass / fail | I16: Instructor comment
A17: S-01
A18: S-02
A19: S-03
A20: S-04
A21: S-05
A22: S-06
A23: S-07
A24: S-08
A25: S-09
A26: S-10
A27: S-11
A28: S-12
... A31: S-15
E33: Invalid tests recorded | F33: =COUNTA(B17:B31) -> 0
E34: Check (need at least 5) | F34: =IF(F33>=5,"OK","Need at least 5") -> Need at least 5
A36: Examples of invalid moves: Delivered to Preparing, Cancelled to Confirmed, Preparing to Cancelled, Ready to Delivered, Placed to Ready.

Sheet RTM
A1: Requirements Traceability Matrix
A2: Links every FR and NFR to its use case, design element, code component and test cases. IDs and requirement text come from the Requirements sheet.
A4: ID | B4: Requirement | C4: Use case | D4: Design element (diagram / class) | E4: Code component (class / file) | F4: Test IDs | G4: Verdict | H4: No test? | I4: Instructor comment
A5: =IF(Requirements!A5="","",Requirements!A5) -> FR-A1 | B5: =IF(Requirements!B5="","",Requirements!B5) -> The system shall let an administrator create a brand (name, description, operating hubs) and create its menu items (name, category, positive VND price, brand and availability). | C5: =IF(Requirements!E5="","",Requirements!E5) -> A | D5: Planned: Brand entity, menu admin | E5: Planned: BrandsController | F5: TC-A-01 | G5: Not tested | H5: =IF(A5="","",IF(F5="","No test","OK")) -> OK
A6: =IF(Requirements!A6="","",Requirements!A6) -> FR-A2 | B6: =IF(Requirements!B6="","",Requirements!B6) -> The system shall let any visitor view brands and menu items filtered by hub and by category. | C6: =IF(Requirements!E6="","",Requirements!E6) -> A | D6: Planned: Catalogue view | E6: Planned: BrandsController | F6: TC-A-02 | G6: Not tested | H6: =IF(A6="","",IF(F6="","No test","OK")) -> OK
A7: =IF(Requirements!A7="","",Requirements!A7) -> FR-A3 | B7: =IF(Requirements!B7="","",Requirements!B7) -> The system shall let an administrator edit brand details and a menu item’s name, category, price and brand. | C7: =IF(Requirements!E7="","",Requirements!E7) -> A | D7: Planned: Menu edit form | E7: Planned: BrandsController | F7: TC-A-03 | G7: Not tested | H7: =IF(A7="","",IF(F7="","No test","OK")) -> OK
A8: =IF(Requirements!A8="","",Requirements!A8) -> FR-A4 | B8: =IF(Requirements!B8="","",Requirements!B8) -> The system shall soft-delete brands and menu items, so that historical orders and reports keep their names and prices. | C8: =IF(Requirements!E8="","",Requirements!E8) -> A | D8: Planned: Soft-delete filter | E8: Planned: DbContext filters | F8: TC-A-04 | G8: Not tested | H8: =IF(A8="","",IF(F8="","No test","OK")) -> OK
A9: =IF(Requirements!A9="","",Requirements!A9) -> FR-A5 | B9: =IF(Requirements!B9="","",Requirements!B9) -> The system shall let an administrator set item availability; unavailable or inactive items shall not be orderable. | C9: =IF(Requirements!E9="","",Requirements!E9) -> A | D9: Planned: Availability flag | E9: Planned: MenuItemService | F9: TC-A-05 | G9: Not tested | H9: =IF(A9="","",IF(F9="","No test","OK")) -> OK
A10: =IF(Requirements!A10="","",Requirements!A10) -> FR-A6 | B10: =IF(Requirements!B10="","",Requirements!B10) -> The system shall reject any order line whose item belongs to a brand the chosen hub does not operate. | C10: =IF(Requirements!E10="","",Requirements!E10) -> A | D10: Planned: Hub-brand relation | E10: Planned: OrderService | F10: TC-A-06 | G10: Not tested | H10: =IF(A10="","",IF(F10="","No test","OK")) -> OK
A11: =IF(Requirements!A11="","",Requirements!A11) -> FR-B1 | B11: =IF(Requirements!B11="","",Requirements!B11) -> The system shall let an administrator create a hub with a district, an address and a whole-number kitchen capacity greater than zero. | C11: =IF(Requirements!E11="","",Requirements!E11) -> B | D11: Planned: Hub entity | E11: Planned: HubsController | F11: TC-B-01 | G11: Not tested | H11: =IF(A11="","",IF(F11="","No test","OK")) -> OK
A12: =IF(Requirements!A12="","",Requirements!A12) -> FR-B2 | B12: =IF(Requirements!B12="","",Requirements!B12) -> The system shall display hub load as 100 times the count of Confirmed or Preparing orders divided by positive integer kitchen capacity; the new order is not counted. | C12: =IF(Requirements!E12="","",Requirements!E12) -> B | D12: Planned: Derived load | E12: Planned: HubLoadCalculator | F12: TC-B-02 | G12: Not tested | H12: =IF(A12="","",IF(F12="","No test","OK")) -> OK
A13: =IF(Requirements!A13="","",Requirements!A13) -> FR-B3 | B13: =IF(Requirements!B13="","",Requirements!B13) -> The system shall let an administrator edit a hub’s district, address and positive integer capacity, and recompute displayed load after a capacity change. | C13: =IF(Requirements!E13="","",Requirements!E13) -> B | D13: Planned: Capacity edit | E13: Planned: HubsController | F13: TC-B-03 | G13: Not tested | H13: =IF(A13="","",IF(F13="","No test","OK")) -> OK
A14: =IF(Requirements!A14="","",Requirements!A14) -> FR-B4 | B14: =IF(Requirements!B14="","",Requirements!B14) -> The system shall soft-delete a hub, removing it from ordering while preserving its historical orders and report rows. | C14: =IF(Requirements!E14="","",Requirements!E14) -> B | D14: Planned: Soft-delete filter | E14: Planned: DbContext filters | F14: TC-B-04 | G14: Not tested | H14: =IF(A14="","",IF(F14="","No test","OK")) -> OK
A15: =IF(Requirements!A15="","",Requirements!A15) -> FR-B5 | B15: =IF(Requirements!B15="","",Requirements!B15) -> The system shall refuse a new order when the chosen hub’s load is 90 % or above and shall ask the customer to choose another hub. | C15: =IF(Requirements!E15="","",Requirements!E15) -> B | D15: Planned: Admission rule | E15: Planned: OrderAdmissionService | F15: TC-B-05 | G15: Not tested | H15: =IF(A15="","",IF(F15="","No test","OK")) -> OK
A16: =IF(Requirements!A16="","",Requirements!A16) -> FR-C1 | B16: =IF(Requirements!B16="","",Requirements!B16) -> The system shall let an administrator create a voucher with a code, a type (PERCENT or FIXED), a value, a maximum discount, a minimum subtotal, validity dates and an active flag. | C16: =IF(Requirements!E16="","",Requirements!E16) -> C | D16: Planned: Voucher entity | E16: Planned: VouchersController | F16: TC-C-01 | G16: Not tested | H16: =IF(A16="","",IF(F16="","No test","OK")) -> OK
... A57: =IF(Requirements!A57="","",Requirements!A57) -> NFR6 | B57: =IF(Requirements!B57="","",Requirements!B57) -> Reliability: Zero forbidden transitions are accepted; repeated pricing with identical lines and the stored placement snapshot returns identical components and rounded total. | C57: =IF(Requirements!E57="","",Requirements!E57) -> D/F | D57: Planned: Order state machine and price snapshot | E57: Planned: Order state machine and price snapshot | F57: TC-NFR-6 | G57: Not tested | H57: =IF(A57="","",IF(F57="","No test","OK")) -> OK
B59: Requirements with a verdict of Pass | C59: =COUNTIF(G5:G57,"Pass") -> 0
B60: Requirements without any test ID | C60: =COUNTIF(H5:H57,"No test") -> 0

Sheet Change Request
A1: Change Request Impact Note
A2: Issued by the instructor in Week 5 (for example a new payment method or pricing rule). A well-designed system absorbs it with small, local changes.
A3: Impact note
A4: Item | B4: Your answer
A5: Change Request (what was asked)
A6: Date received
A7: Requirements affected (FR / BR)
A8: Summary of the solution
A9: Effort (hours) and who did it
A10: What was easy or hard, and why
A11: Existing payment classes edited? (should be No)
A13: Class change list
A14: Class / file | B14: What changed | C14: Added or modified | D14: Existing payment class? | E14: Commit link (evidence) | F14: Instructor comment
A31: Classes added | B31: =COUNTIF(C15:C29,"Added") -> 0
A32: Classes modified | B32: =COUNTIF(C15:C29,"Modified") -> 0
A33: Existing payment classes modified | B33: =COUNTIFS(C15:C29,"Modified",D15:D29,"Yes") -> 0
A35: Modifying an existing payment class (red row) suggests the Strategy pattern was not applied well. Explain it in the impact note.

Sheet Tier Checklist
A1: Tier Checklist
A2: The tier cap applies only if the delivered system really uses the stack of the tier (a mixed stack is graded at the lower tier).
A4: # | B4: Requirement | C4: Student | D4: Instructor | E4: Notes / evidence
B5: All tiers
A6: 1 | B6: Delivered stack matches the chosen tier | E6: Proposed ASP.NET Core MVC + EF Core Code-First + SQL Server + Bootstrap 5. Instructor confirmation of Core variant pending.
A7: 2 | B7: 3-Tier (Tier 1) or MVC (other tiers) is enforced in the code, not only in the diagrams | E7: Planned MVC controllers/views, business services and EF persistence. Verify actual separation in Parts 2/3.
A8: 3 | B8: Web tiers use Bootstrap (responsive grid) | E8: Planned Bootstrap responsive layout; test 390, 768 and 1440 px with English/Vietnamese.
A9: 4 | B9: Payment methods use the Strategy pattern (interface, one class per method, selection by actor type) | E9: Planned payment Strategy per method and actor; extension test: one new class plus registration.
A10: 5 | B10: Pricing rules BR1 to BR14 live in one business-layer module, not in the UI | E10: Planned pure PricingEngine with placement snapshot; test BR1–BR14 boundaries and eligibility in services.
A11: 6 | B11: Order state machine is enforced in the business layer (BR15) | E11: Planned business-layer OrderStateMachine; cover every allowed and at least 5 forbidden transitions.
A12: 7 | B12: Both reports R1 (Revenue) and R2 (Hub Utilization) work | E12: Planned R1 Revenue and R2 Hub Utilization with authorised queries and reconciled totals.
A13: 8 | B13: Tagged GitHub release is the submission; the application runs from it | E13: Tagged GitHub release and clean runbook are later deliverables; not verified in this Part 1 revision.
B14: Tier 4 only
A15: 9 | B15: (a) Live sandbox API integration (VNPay Sandbox or PayPal Developer) works | E15: Planned live VNPay sandbox. Owner 524H0195. Require real success/failure callbacks, authentication, amount/order checks and replay-safe handling; mock is insufficient.
A16: 10 | B16: (b) Interactive Admin dashboard | E16: Planned interactive R1/R2 Admin dashboard. Owners 524H0191 / 524H0179. Require working filters, matching chart/table totals and role denial.
A17: 11 | B17: (c) Automated tests of core workflows (for example Selenium or Playwright) with logs | E17: Planned unit/integration/E2E execution with retained logs, at least 20 EP/BVA and 5 forbidden transitions. Every member covers their scope.

Sheet Contribution & Commits
A1: Contribution Statement Draft and GitHub Commits
A2: More than 10 meaningful commits per student, touching the student's own use case. The signed one-page Contribution Statement is handed in at the start of Part 3.
A4: Member | B4: Name | C4: Student ID | D4: Commits on GitHub | E4: Use case(s) owned | F4: Classes, components and report sections owned | G4: Evidence (commit links, pull requests) | H4: Instructor comment
A5: Member 1 | B5: Ngô Lâm Tiến | C5: 524H0195 | D5: Not verified | E5: D; C - Manage Vouchers; Pricing Engine (BR1-BR12); Payment Strategy Module | F5: Planned ownership: Place and Manage Orders; pricing/payments. Planned peer reviewer: 524H0179. Review shared interfaces and joint acceptance cases. | G5: Planned evidence: scoped PRs, peer-review comments and linked FR/test IDs. Reviewer 524H0179; commit counts and completed reviews not audited.
A6: Member 2 | B6: Nguyễn Công Thành | C6: 524H0191 | D6: Not verified | E6: A; E - Manage User Accounts | F6: Planned ownership: Manage Menu & Brands; R1 - Revenue Report. Planned peer reviewer: 524H0195. Review shared interfaces and joint acceptance cases. | G6: Planned evidence: scoped PRs, peer-review comments and linked FR/test IDs. Reviewer 524H0195; commit counts and completed reviews not audited.
A7: Member 3 | B7: Nguyễn Trọng Phú | C7: 524H0179 | D7: Not verified | E7: B; F - Manage Deliveries; Change Request Impact Note | F7: Planned ownership: Manage Hubs & Capacity; R2 - Hub Utilization Report. Planned peer reviewer: 524H0191. Review shared interfaces and joint acceptance cases. | G7: Planned evidence: scoped PRs, peer-review comments and linked FR/test IDs. Reviewer 524H0191; commit counts and completed reviews not audited.
A9: Commit counts of 10 or fewer are highlighted red. The Contribution Factor (0.70 to 1.00) uses this sheet, the GitHub history, the signed statement, the peer review and the individual questions in Presentations 2 and 3.
A11: Weekly contribution log (optional but recommended)
A12: Week | B12: Student ID | C12: What I did | D12: Hours | E12: Commit / link | F12: Blockers | G12: Instructor comment

Sheet AI Usage Log
A1: Generative AI Usage Log
A2: One row per use. Keep the full prompts and outputs in a separate file (Appendix B) and hand them over within 48 hours if asked.
A4: No. | B4: Tool and date | C4: Purpose | D4: Prompt (summary) | E4: What you kept or changed | F4: How you verified it | G4: Student ID | H4: Instructor comment
A5: 1 | B5: DeepSeek Harness (DSH), 23 Oct 2026 | C5: Earlier draft and project scaffolding | D5: Earlier project log describes extraction of BRs, FR drafting, architecture and rendering. This is a summary from that log, not a recovered raw prompt. | E5: Retained the useful document structure and stable FR IDs; corrected conflicting thresholds, ownership and unsupported claims during this revision. | F5: Compared current requirements with the three course PDFs; earlier raw prompts/outputs are not available in this workspace. | G5: TeamG4 (team-wide assistance)
A6: 2 | B6: OpenAI Codex, 24 Oct 2026 | C6: Strict Part 1 audit | D6: User requested a lecturer-style audit of existing Part 1 against the screenshot, course requirements, templates and TDTU skills. | E6: Recorded faults and repair priorities in PART1_AUDIT_2026-10-24.md; did not use the provisional score as an official course mark. | F6: Read the course PDFs, extracted workbook cells, rendered report/slides, checked links and calculated the rounding counterexample independently. | G6: TeamG4 (team-wide assistance)
A7: 3 | B7: OpenAI Codex, 24 Oct 2026 | C7: Correct and synchronise Part 1 deliverables | D7: User: “ok giờ bạn cứ sửa sao cho chuẩn nhất đi đẻ hoàn thiện part 1”. | E7: One shared FR/NFR/ambiguity register, corrected report/workbook/pitch and explicit planned verification. No invented signatures or instructor answers. | F7: Build and source-consistency checks; rendered output checks are recorded in the Part 1 verification note. Live pitch, sandbox and application tests are outside this document revision. | G7: TeamG4 (team-wide assistance)
A8: 4 | B8: OpenAI Codex, 25 Oct 2026 | C8: Align team Excel with the instructor original | D8: User requested the original SE_Sem01_2627_Team_Workbook_Template.xlsx and authorised implementation once downloaded. | E8: Retained all 14 sheets, original headers and student/instructor input colours. Mapped 47 FR, 6 NFR, 5 ambiguities; extended Requirements/RTM by 8 rows. | F8: Source hash, template features, canonical records, formulas and rendered ranges checked. No instructor answer, tested verdict or individual commit count invented. | G8: TeamG4 (team-wide assistance)
A9: 5 | B9: OpenAI Codex, 25 Oct 2026 | C9: Clarify planned team collaboration | D9: The team requested clearer teamwork and stronger evidence in its Excel deliverables. | E9: Added named planned peer reviewers, joint contract/requirements/integration tasks and future PR/review/test evidence. Main ownership and requirement IDs retained. | F9: Template fidelity, reviewer separation, task status and synchronisation checked. No completed meeting, review, commit count or test result invented. | G9: TeamG4 (team-wide assistance)
A10: 6
A11: 7
A12: 8
A13: 9
A14: 10
A15: 11
A16: 12
A17: 13
A18: 14
A19: 15
A20: 16
A21: 17
... A44: 40

Sheet Feedback Log
A1: Feedback Log
A2: The final report must show that you applied the feedback from the previous presentations. Record each item and what you changed.
A4: Source | B4: Feedback received | C4: What we changed and where | D4: Report section | E4: Done | F4: Instructor comment
